Workbook
Name Slicer_Department_Name: #N/A
Name Slicer_EmploymentStatus: #N/A
Name Slicer_Performance_Band: #N/A

Sheet Lookup Department
A1: Dept_Code | B1: Department_Name
A2: HR01 | B2: Human Resources | C2: =VLOOKUP(A2,A1:B7,2,FALSE) -> Human Resources
A3: IT02 | B3: Information Technology | C3: =VLOOKUP(A3,A2:B8,2,FALSE) -> Information Technology
A4: FIN03 | B4: Finance | C4: =VLOOKUP(A4,A3:B9,2,FALSE) -> Finance
A5: MKT04 | B5: Marketing | C5: =VLOOKUP(A5,A4:B10,2,FALSE) -> Marketing
A6: SAL05 | B6: Sales | C6: =VLOOKUP(A6,A5:B11,2,FALSE) -> Sales
A7: OPS06 | B7: Operations | C7: =VLOOKUP(A7,A6:B12,2,FALSE) -> Operations

Sheet Lookup_Performance
A1: Min_Score | B1: Max_Score | C1: Performance_Band | D1: Bonus_Percentage
A2: 0 | B2: 49 | C2: Needs Improvement | D2: 0
A3: 50 | B3: 69 | C3: Developing | D3: 0.02
A4: 70 | B4: 84 | C4: Achieving | D4: 0.05
A5: 85 | B5: 94 | C5: Exceeding | D5: 0.08
A6: 95 | B6: 100 | C6: Outstanding | D6: 0.12

Sheet PIVOTS TABLE
A3: Head Count and Salary | G3: Peformance By Status
A5: Department | B5: Count of Salary | G5: Performance Band | H5: Sum of Eligible Bonus Amount
A6: Finance | B6: 17 | G6: Achieving | H6: 164994.31
A7: Human Resources | B7: 18 | G7: Developing | H7: 84450.789
A8: Information Technology | B8: 36 | G8: Exceeding | H8: 144546.95
A9: Marketing | B9: 19 | G9: Needs Improvement | H9: 0
A10: Operations | B10: 29 | G10: Outstanding | H10: 92304.652
A11: Sales | B11: 31 | G11: Grand Total | H11: 486296.7
A12: Grand Total | B12: 150
G14: Attrition Rate
G16: Count of Emp ID | H16: Column Labels
G17: Row Labels | H17: No | I17: Yes | J17: Grand Total
G18: Finance | H18: 0.82352941 | I18: 0.17647059 | J18: 1
G19: Human Resources | H19: 0.83333333 | I19: 0.16666667 | J19: 1
G20: Information Technology | H20: 0.77777778 | I20: 0.22222222 | J20: 1
G21: Marketing | H21: 0.84210526 | I21: 0.15789474 | J21: 1
G22: Operations | H22: 0.62068966 | I22: 0.37931034 | J22: 1
A23: Bonus Payout | G23: Sales | H23: 0.80645161 | I23: 0.19354839 | J23: 1
G24: Grand Total | H24: 0.77333333 | I24: 0.22666667 | J24: 1 | K24: =GETPIVOTDATA("Emp ID",$G$16,"Attrition Rate","Yes") -> 0.22666667
A25: Employment Status | B25: Average of Perf_Score
A26: Active | B26: 67.741379
A27: Left | B27: 66.208333
A28: Grand Total | B28: 67.478571
A34: Row Labels | B34: Average of Salary | G34: Row Labels | H34: Count of EmploymentStatus
A35: Finance | B35: 92544.107 | G35: Finance | H35: 8
A36: Human Resources | B36: 100093 | G36: Human Resources | H36: 2
A37: Information Technology | B37: 82747.924 | G37: Information Technology | H37: 15 | J37: Count of Emp ID
A38: Marketing | B38: 94072.5 | G38: Marketing | H38: 2 | J38: 150 | K38: =GETPIVOTDATA("Emp ID",$J$37) -> 150
A39: Operations | B39: 91356.5 | G39: Operations | H39: 4
A40: Sales | B40: 83329.372 | G40: Sales | H40: 10
A41: Grand Total | B41: 87039.572 | C41: =GETPIVOTDATA("Salary",$A$34) -> 87039.572 | G41: Grand Total | H41: 41
G44: Row Labels | H44: Count of EMP ID
G45: Finance | H45: 8 | K45: Row Labels | L45: Average of Salary
G46: Human Resources | H46: 2 | K46: Finance | L46: 92544.107
G47: Information Technology | H47: 15 | K47: Human Resources | L47: 100093
A48: Row Labels | B48: Average of Perf_Score | G48: Marketing | H48: 2 | K48: Information Technology | L48: 82747.924
A49: Active | B49: 60.272727 | G49: Operations | H49: 4 | K49: Marketing | L49: 94072.5
A50: Left | B50: 57.833333 | G50: Sales | H50: 10 | K50: Operations | L50: 91356.5
A51: Resigned | B51: 60 | G51: Grand Total | H51: 41 | K51: Sales | L51: 83329.372
A52: Grand Total | B52: 59.902439 | K52: Grand Total | L52: 87039.572
...

Sheet HR DASHBAORD
T15: Z

Sheet Raw_Employee Data
A1: Emp ID | B1: Full Name | C1: Dept Code | D1: Hire Date | E1: Years of Service | F1: Salary | G1: Perf_Score | H1: Employment Status | I1: Department_Name | J1: Performance Bond | K1: Eligible Bonus Amount | L1: Attrition Rate
A2: EMP127 | B2: Emily Brown | C2: IT02 | D2: 43093 | E2: =DATEDIF(D2,TODAY(),"Y")&" Years, "&DATEDIF(D2,TODAY(),"YM")&" Months" -> 8 Years, 6 Months | F2: 50361 | G2: 52 | H2: Active | I2: =VLOOKUP(TRIM(C2),'Lookup Department'!$A$1:$B$7,2,FALSE) -> Information Technology | J2: =IF(G2<=49,"Needs Improvement", IF(G2<=69,"Developing", IF(G2<=84,"Achieving", IF(G2<=94,"Exceeding", "Outstanding")))) -> Developing | K2: =IF(J2="Needs Improvement",F2*0, IF(J2="Developing",F2*0.02, IF(J2="Achieving",F2*0.05, IF(J2="Exceeding",F2*0.08, IF(J2="Outstanding",F2*0.12,0))))) -> 1007.22 | L2: {=_xlfn.IFS(Table2[[#This Row],[Employment Status]]="Left","Yes",Table2[[#This Row],[Employment Status]]="Resigned","Yes","TRUE","No")} -> No
A3: EMP046 | B3: Richard Hernandez | C3: MKT04 | D3: 44659 | E3: =DATEDIF(D3,TODAY(),"Y")&" Years, "&DATEDIF(D3,TODAY(),"YM")&" Months" -> 4 Years, 3 Months | F3: 112673 | G3: 68 | H3: Active | I3: =VLOOKUP(TRIM(C3),'Lookup Department'!$A$1:$B$7,2,FALSE) -> Marketing | J3: =IF(G3<=49,"Needs Improvement", IF(G3<=69,"Developing", IF(G3<=84,"Achieving", IF(G3<=94,"Exceeding", "Outstanding")))) -> Developing | K3: =IF(J3="Needs Improvement",F3*0, IF(J3="Developing",F3*0.02, IF(J3="Achieving",F3*0.05, IF(J3="Exceeding",F3*0.08, IF(J3="Outstanding",F3*0.12,0))))) -> 2253.46 | L3: {=_xlfn.IFS(Table2[[#This Row],[Employment Status]]="Left","Yes",Table2[[#This Row],[Employment Status]]="Resigned","Yes","TRUE","No")} -> No
A4: EMP134 | B4: Emily Gonzalez | C4: IT02 | D4: 42431 | E4: =DATEDIF(D4,TODAY(),"Y")&" Years, "&DATEDIF(D4,TODAY(),"YM")&" Months" -> 10 Years, 4 Months | F4: 114425 | G4: 54 | H4: Left | I4: =VLOOKUP(TRIM(C4),'Lookup Department'!$A$1:$B$7,2,FALSE) -> Information Technology | J4: =IF(G4<=49,"Needs Improvement", IF(G4<=69,"Developing", IF(G4<=84,"Achieving", IF(G4<=94,"Exceeding", "Outstanding")))) -> Developing | K4: =IF(J4="Needs Improvement",F4*0, IF(J4="Developing",F4*0.02, IF(J4="Achieving",F4*0.05, IF(J4="Exceeding",F4*0.08, IF(J4="Outstanding",F4*0.12,0))))) -> 2288.5 | L4: {=_xlfn.IFS(Table2[[#This Row],[Employment Status]]="Left","Yes",Table2[[#This Row],[Employment Status]]="Resigned","Yes","TRUE","No")} -> Yes
A5: EMP139 | B5: John Martinez | C5: FIN03 | D5: 45110 | E5: =DATEDIF(D5,TODAY(),"Y")&" Years, "&DATEDIF(D5,TODAY(),"YM")&" Months" -> 3 Years, 0 Months | F5: 103831 | G5: 70 | H5: Active | I5: =VLOOKUP(TRIM(C5),'Lookup Department'!$A$1:$B$7,2,FALSE) -> Finance | J5: =IF(G5<=49,"Needs Improvement", IF(G5<=69,"Developing", IF(G5<=84,"Achieving", IF(G5<=94,"Exceeding", "Outstanding")))) -> Achieving | K5: =IF(J5="Needs Improvement",F5*0, IF(J5="Developing",F5*0.02, IF(J5="Achieving",F5*0.05, IF(J5="Exceeding",F5*0.08, IF(J5="Outstanding",F5*0.12,0))))) -> 5191.55 | L5: {=_xlfn.IFS(Table2[[#This Row],[Employment Status]]="Left","Yes",Table2[[#This Row],[Employment Status]]="Resigned","Yes","TRUE","No")} -> No
A6: EMP112 | B6: Thomas Smith | C6: IT02 | D6: 44977 | E6: =DATEDIF(D6,TODAY(),"Y")&" Years, "&DATEDIF(D6,TODAY(),"YM")&" Months" -> 3 Years, 4 Months | F6: 73785 | G6: 40 | H6: Left | I6: =VLOOKUP(TRIM(C6),'Lookup Department'!$A$1:$B$7,2,FALSE) -> Information Technology | J6: =IF(G6<=49,"Needs Improvement", IF(G6<=69,"Developing", IF(G6<=84,"Achieving", IF(G6<=94,"Exceeding", "Outstanding")))) -> Needs Improvement | K6: =IF(J6="Needs Improvement",F6*0, IF(J6="Developing",F6*0.02, IF(J6="Achieving",F6*0.05, IF(J6="Exceeding",F6*0.08, IF(J6="Outstanding",F6*0.12,0))))) -> 0 | L6: {=_xlfn.IFS(Table2[[#This Row],[Employment Status]]="Left","Yes",Table2[[#This Row],[Employment Status]]="Resigned","Yes","TRUE","No")} -> Yes
A7: EMP030 | B7: Emily Johnson | C7: OPS06 | D7: 43892 | E7: =DATEDIF(D7,TODAY(),"Y")&" Years, "&DATEDIF(D7,TODAY(),"YM")&" Months" -> 6 Years, 4 Months | F7: 115882 | G7: 49 | H7: Active | I7: =VLOOKUP(TRIM(C7),'Lookup Department'!$A$1:$B$7,2,FALSE) -> Operations | J7: =IF(G7<=49,"Needs Improvement", IF(G7<=69,"Developing", IF(G7<=84,"Achieving", IF(G7<=94,"Exceeding", "Outstanding")))) -> Needs Improvement | K7: =IF(J7="Needs Improvement",F7*0, IF(J7="Developing",F7*0.02, IF(J7="Achieving",F7*0.05, IF(J7="Exceeding",F7*0.08, IF(J7="Outstanding",F7*0.12,0))))) -> 0 | L7: {=_xlfn.IFS(Table2[[#This Row],[Employment Status]]="Left","Yes",Table2[[#This Row],[Employment Status]]="Resigned","Yes","TRUE","No")} -> No
A8: EMP096 | B8: John Wilson | C8: OPS06 | D8: 45272 | E8: =DATEDIF(D8,TODAY(),"Y")&" Years, "&DATEDIF(D8,TODAY(),"YM")&" Months" -> 2 Years, 6 Months | F8: 59980 | G8: 70 | H8: Left | I8: =VLOOKUP(TRIM(C8),'Lookup Department'!$A$1:$B$7,2,FALSE) -> Operations | J8: =IF(G8<=49,"Needs Improvement", IF(G8<=69,"Developing", IF(G8<=84,"Achieving", IF(G8<=94,"Exceeding", "Outstanding")))) -> Achieving | K8: =IF(J8="Needs Improvement",F8*0, IF(J8="Developing",F8*0.02, IF(J8="Achieving",F8*0.05, IF(J8="Exceeding",F8*0.08, IF(J8="Outstanding",F8*0.12,0))))) -> 2999 | L8: {=_xlfn.IFS(Table2[[#This Row],[Employment Status]]="Left","Yes",Table2[[#This Row],[Employment Status]]="Resigned","Yes","TRUE","No")} -> Yes
A9: EMP098 | B9: Jessica Smith | C9: OPS06 | D9: 44174 | E9: =DATEDIF(D9,TODAY(),"Y")&" Years, "&DATEDIF(D9,TODAY(),"YM")&" Months" -> 5 Years, 6 Months | F9: 68728 | G9: 45 | H9: Active | I9: =VLOOKUP(TRIM(C9),'Lookup Department'!$A$1:$B$7,2,FALSE) -> Operations | J9: =IF(G9<=49,"Needs Improvement", IF(G9<=69,"Developing", IF(G9<=84,"Achieving", IF(G9<=94,"Exceeding", "Outstanding")))) -> Needs Improvement | K9: =IF(J9="Needs Improvement",F9*0, IF(J9="Developing",F9*0.02, IF(J9="Achieving",F9*0.05, IF(J9="Exceeding",F9*0.08, IF(J9="Outstanding",F9*0.12,0))))) -> 0 | L9: {=_xlfn.IFS(Table2[[#This Row],[Employment Status]]="Left","Yes",Table2[[#This Row],[Employment Status]]="Resigned","Yes","TRUE","No")} -> No
A10: EMP095 | B10: Rodriguez | C10: FIN03 | D10: 43107 | E10: =DATEDIF(D10,TODAY(),"Y")&" Years, "&DATEDIF(D10,TODAY(),"YM")&" Months" -> 8 Years, 6 Months | F10: 102139 | G10: 79 | H10: Active | I10: =VLOOKUP(TRIM(C10),'Lookup Department'!$A$1:$B$7,2,FALSE) -> Finance | J10: =IF(G10<=49,"Needs Improvement", IF(G10<=69,"Developing", IF(G10<=84,"Achieving", IF(G10<=94,"Exceeding", "Outstanding")))) -> Achieving | K10: =IF(J10="Needs Improvement",F10*0, IF(J10="Developing",F10*0.02, IF(J10="Achieving",F10*0.05, IF(J10="Exceeding",F10*0.08, IF(J10="Outstanding",F10*0.12,0))))) -> 5106.95 | L10: {=_xlfn.IFS(Table2[[#This Row],[Employment Status]]="Left","Yes",Table2[[#This Row],[Employment Status]]="Resigned","Yes","TRUE","No")} -> No
A11: EMP140 | B11: Michael Martinez | C11: SAL05 | D11: 42676 | E11: =DATEDIF(D11,TODAY(),"Y")&" Years, "&DATEDIF(D11,TODAY(),"YM")&" Months" -> 9 Years, 8 Months | F11: 94998 | G11: 58 | H11: Active | I11: =VLOOKUP(TRIM(C11),'Lookup Department'!$A$1:$B$7,2,FALSE) -> Sales | J11: =IF(G11<=49,"Needs Improvement", IF(G11<=69,"Developing", IF(G11<=84,"Achieving", IF(G11<=94,"Exceeding", "Outstanding")))) -> Developing | K11: =IF(J11="Needs Improvement",F11*0, IF(J11="Developing",F11*0.02, IF(J11="Achieving",F11*0.05, IF(J11="Exceeding",F11*0.08, IF(J11="Outstanding",F11*0.12,0))))) -> 1899.96 | L11: {=_xlfn.IFS(Table2[[#This Row],[Employment Status]]="Left","Yes",Table2[[#This Row],[Employment Status]]="Resigned","Yes","TRUE","No")} -> No
A12: EMP020 | B12: Emily Miller | C12: SAL05 | D12: 43911 | E12: =DATEDIF(D12,TODAY(),"Y")&" Years, "&DATEDIF(D12,TODAY(),"YM")&" Months" -> 6 Years, 3 Months | F12: 118635 | G12: 49 | H12: Active | I12: =VLOOKUP(TRIM(C12),'Lookup Department'!$A$1:$B$7,2,FALSE) -> Sales | J12: =IF(G12<=49,"Needs Improvement", IF(G12<=69,"Developing", IF(G12<=84,"Achieving", IF(G12<=94,"Exceeding", "Outstanding")))) -> Needs Improvement | K12: =IF(J12="Needs Improvement",F12*0, IF(J12="Developing",F12*0.02, IF(J12="Achieving",F12*0.05, IF(J12="Exceeding",F12*0.08, IF(J12="Outstanding",F12*0.12,0))))) -> 0 | L12: {=_xlfn.IFS(Table2[[#This Row],[Employment Status]]="Left","Yes",Table2[[#This Row],[Employment Status]]="Resigned","Yes","TRUE","No")} -> No
A13: EMP057 | B13: Emily Hernandez | C13: IT02 | D13: 42425 | E13: =DATEDIF(D13,TODAY(),"Y")&" Years, "&DATEDIF(D13,TODAY(),"YM")&" Months" -> 10 Years, 4 Months | F13: 76918 | G13: 62 | H13: Active | I13: =VLOOKUP(TRIM(C13),'Lookup Department'!$A$1:$B$7,2,FALSE) -> Information Technology | J13: =IF(G13<=49,"Needs Improvement", IF(G13<=69,"Developing", IF(G13<=84,"Achieving", IF(G13<=94,"Exceeding", "Outstanding")))) -> Developing | K13: =IF(J13="Needs Improvement",F13*0, IF(J13="Developing",F13*0.02, IF(J13="Achieving",F13*0.05, IF(J13="Exceeding",F13*0.08, IF(J13="Outstanding",F13*0.12,0))))) -> 1538.36 | L13: {=_xlfn.IFS(Table2[[#This Row],[Employment Status]]="Left","Yes",Table2[[#This Row],[Employment Status]]="Resigned","Yes","TRUE","No")} -> No
... A95: EMP147 | B95: Thomas Miller | C95: OPS06 | D95: 43112 | E95: =DATEDIF(D95,TODAY(),"Y")&" Years, "&DATEDIF(D95,TODAY(),"YM")&" Months" -> 8 Years, 5 Months | F95: 67414 | G95: 84 | H95: Left | I95: =VLOOKUP(TRIM(C95),'Lookup Department'!$A$1:$B$7,2,FALSE) -> Operations | J95: =IF(G95<=49,"Needs Improvement", IF(G95<=69,"Developing", IF(G95<=84,"Achieving", IF(G95<=94,"Exceeding", "Outstanding")))) -> Achieving | K95: =IF(J95="Needs Improvement",F95*0, IF(J95="Developing",F95*0.02, IF(J95="Achieving",F95*0.05, IF(J95="Exceeding",F95*0.08, IF(J95="Outstanding",F95*0.12,0))))) -> 3370.7 | L95: {=_xlfn.IFS(Table2[[#This Row],[Employment Status]]="Left","Yes",Table2[[#This Row],[Employment Status]]="Resigned","Yes","TRUE","No")} -> Yes
A96: EMP050 | B96: William Gonzalez | C96: SAL05 | D96: 42008 | E96: =DATEDIF(D96,TODAY(),"Y")&" Years, "&DATEDIF(D96,TODAY(),"YM")&" Months" -> 11 Years, 6 Months | F96: $115,288 | G96: 61 | H96: Active | I96: =VLOOKUP(TRIM(C96),'Lookup Department'!$A$1:$B$7,2,FALSE) -> Sales | J96: =IF(G96<=49,"Needs Improvement", IF(G96<=69,"Developing", IF(G96<=84,"Achieving", IF(G96<=94,"Exceeding", "Outstanding")))) -> Developing | K96: =IF(J96="Needs Improvement",F96*0, IF(J96="Developing",F96*0.02, IF(J96="Achieving",F96*0.05, IF(J96="Exceeding",F96*0.08, IF(J96="Outstanding",F96*0.12,0))))) -> 2305.76 | L96: {=_xlfn.IFS(Table2[[#This Row],[Employment Status]]="Left","Yes",Table2[[#This Row],[Employment Status]]="Resigned","Yes","TRUE","No")} -> No
A97: EMP036 | B97: Smith | C97: SAL05 | D97: 43439 | E97: =DATEDIF(D97,TODAY(),"Y")&" Years, "&DATEDIF(D97,TODAY(),"YM")&" Months" -> 7 Years, 7 Months | F97: 80140 | G97: 58 | H97: Active | I97: =VLOOKUP(TRIM(C97),'Lookup Department'!$A$1:$B$7,2,FALSE) -> Sales | J97: =IF(G97<=49,"Needs Improvement", IF(G97<=69,"Developing", IF(G97<=84,"Achieving", IF(G97<=94,"Exceeding", "Outstanding")))) -> Developing | K97: =IF(J97="Needs Improvement",F97*0, IF(J97="Developing",F97*0.02, IF(J97="Achieving",F97*0.05, IF(J97="Exceeding",F97*0.08, IF(J97="Outstanding",F97*0.12,0))))) -> 1602.8 | L97: {=_xlfn.IFS(Table2[[#This Row],[Employment Status]]="Left","Yes",Table2[[#This Row],[Employment Status]]="Resigned","Yes","TRUE","No")} -> No
A98: EMP081 | B98: John Johnson | C98: IT02 | D98: 44482 | E98: =DATEDIF(D98,TODAY(),"Y")&" Years, "&DATEDIF(D98,TODAY(),"YM")&" Months" -> 4 Years, 8 Months | F98: 73087 | G98: 69 | H98: Active | I98: =VLOOKUP(TRIM(C98),'Lookup Department'!$A$1:$B$7,2,FALSE) -> Information Technology | J98: =IF(G98<=49,"Needs Improvement", IF(G98<=69,"Developing", IF(G98<=84,"Achieving", IF(G98<=94,"Exceeding", "Outstanding")))) -> Developing | K98: =IF(J98="Needs Improvement",F98*0, IF(J98="Developing",F98*0.02, IF(J98="Achieving",F98*0.05, IF(J98="Exceeding",F98*0.08, IF(J98="Outstanding",F98*0.12,0))))) -> 1461.74 | L98: {=_xlfn.IFS(Table2[[#This Row],[Employment Status]]="Left","Yes",Table2[[#This Row],[Employment Status]]="Resigned","Yes","TRUE","No")} -> No
A99: EMP078 | B99: Jane Johnson | C99: SAL05 | D99: 44081 | E99: =DATEDIF(D99,TODAY(),"Y")&" Years, "&DATEDIF(D99,TODAY(),"YM")&" Months" -> 5 Years, 10 Months | F99: 95292 | G99: 34 | H99: Active | I99: =VLOOKUP(TRIM(C99),'Lookup Department'!$A$1:$B$7,2,FALSE) -> Sales | J99: =IF(G99<=49,"Needs Improvement", IF(G99<=69,"Developing", IF(G99<=84,"Achieving", IF(G99<=94,"Exceeding", "Outstanding")))) -> Needs Improvement | K99: =IF(J99="Needs Improvement",F99*0, IF(J99="Developing",F99*0.02, IF(J99="Achieving",F99*0.05, IF(J99="Exceeding",F99*0.08, IF(J99="Outstanding",F99*0.12,0))))) -> 0 | L99: {=_xlfn.IFS(Table2[[#This Row],[Employment Status]]="Left","Yes",Table2[[#This Row],[Employment Status]]="Resigned","Yes","TRUE","No")} -> No
A100: EMP035 | B100: John Jones | C100: IT02 | D100: 43532 | E100: =DATEDIF(D100,TODAY(),"Y")&" Years, "&DATEDIF(D100,TODAY(),"YM")&" Months" -> 7 Years, 4 Months | F100: 82713.43 | G100: 33 | H100: Active | I100: =VLOOKUP(TRIM(C100),'Lookup Department'!$A$1:$B$7,2,FALSE) -> Information Technology | J100: =IF(G100<=49,"Needs Improvement", IF(G100<=69,"Developing", IF(G100<=84,"Achieving", IF(G100<=94,"Exceeding", "Outstanding")))) -> Needs Improvement | K100: =IF(J100="Needs Improvement",F100*0, IF(J100="Developing",F100*0.02, IF(J100="Achieving",F100*0.05, IF(J100="Exceeding",F100*0.08, IF(J100="Outstanding",F100*0.12,0))))) -> 0 | L100: {=_xlfn.IFS(Table2[[#This Row],[Employment Status]]="Left","Yes",Table2[[#This Row],[Employment Status]]="Resigned","Yes","TRUE","No")} -> No
A101: EMP047 | B101: Jane Lopez | C101: MKT04 | D101: 42074 | E101: =DATEDIF(D101,TODAY(),"Y")&" Years, "&DATEDIF(D101,TODAY(),"YM")&" Months" -> 11 Years, 3 Months | F101: 101750 | G101: 84 | H101: Left | I101: =VLOOKUP(TRIM(C101),'Lookup Department'!$A$1:$B$7,2,FALSE) -> Marketing | J101: =IF(G101<=49,"Needs Improvement", IF(G101<=69,"Developing", IF(G101<=84,"Achieving", IF(G101<=94,"Exceeding", "Outstanding")))) -> Achieving | K101: =IF(J101="Needs Improvement",F101*0, IF(J101="Developing",F101*0.02, IF(J101="Achieving",F101*0.05, IF(J101="Exceeding",F101*0.08, IF(J101="Outstanding",F101*0.12,0))))) -> 5087.5 | L101: {=_xlfn.IFS(Table2[[#This Row],[Employment Status]]="Left","Yes",Table2[[#This Row],[Employment Status]]="Resigned","Yes","TRUE","No")} -> Yes
A102: EMP008 | B102: Melissa Gonzalez | C102: MKT04 | D102: 42785 | E102: =DATEDIF(D102,TODAY(),"Y")&" Years, "&DATEDIF(D102,TODAY(),"YM")&" Months" -> 9 Years, 4 Months | F102: 82992 | G102: 79 | H102: Active | I102: =VLOOKUP(TRIM(C102),'Lookup Department'!$A$1:$B$7,2,FALSE) -> Marketing | J102: =IF(G102<=49,"Needs Improvement", IF(G102<=69,"Developing", IF(G102<=84,"Achieving", IF(G102<=94,"Exceeding", "Outstanding")))) -> Achieving | K102: =IF(J102="Needs Improvement",F102*0, IF(J102="Developing",F102*0.02, IF(J102="Achieving",F102*0.05, IF(J102="Exceeding",F102*0.08, IF(J102="Outstanding",F102*0.12,0))))) -> 4149.6 | L102: {=_xlfn.IFS(Table2[[#This Row],[Employment Status]]="Left","Yes",Table2[[#This Row],[Employment Status]]="Resigned","Yes","TRUE","No")} -> No
A103: EMP044 | B103: William Davis | C103: IT02 | D103: 45055 | E103: =DATEDIF(D103,TODAY(),"Y")&" Years, "&DATEDIF(D103,TODAY(),"YM")&" Months" -> 3 Years, 1 Months | F103: 49942 | G103: 51 | H103: Active | I103: =VLOOKUP(TRIM(C103),'Lookup Department'!$A$1:$B$7,2,FALSE) -> Information Technology | J103: =IF(G103<=49,"Needs Improvement", IF(G103<=69,"Developing", IF(G103<=84,"Achieving", IF(G103<=94,"Exceeding", "Outstanding")))) -> Developing | K103: =IF(J103="Needs Improvement",F103*0, IF(J103="Developing",F103*0.02, IF(J103="Achieving",F103*0.05, IF(J103="Exceeding",F103*0.08, IF(J103="Outstanding",F103*0.12,0))))) -> 998.84 | L103: {=_xlfn.IFS(Table2[[#This Row],[Employment Status]]="Left","Yes",Table2[[#This Row],[Employment Status]]="Resigned","Yes","TRUE","No")} -> No
A104: EMP071 | B104: John Smith | C104: OPS06 | D104: 43122 | E104: =DATEDIF(D104,TODAY(),"Y")&" Years, "&DATEDIF(D104,TODAY(),"YM")&" Months" -> 8 Years, 5 Months | F104: 89060 | G104: 58 | H104: Active | I104: =VLOOKUP(TRIM(C104),'Lookup Department'!$A$1:$B$7,2,FALSE) -> Operations | J104: =IF(G104<=49,"Needs Improvement", IF(G104<=69,"Developing", IF(G104<=84,"Achieving", IF(G104<=94,"Exceeding", "Outstanding")))) -> Developing | K104: =IF(J104="Needs Improvement",F104*0, IF(J104="Developing",F104*0.02, IF(J104="Achieving",F104*0.05, IF(J104="Exceeding",F104*0.08, IF(J104="Outstanding",F104*0.12,0))))) -> 1781.2 | L104: {=_xlfn.IFS(Table2[[#This Row],[Employment Status]]="Left","Yes",Table2[[#This Row],[Employment Status]]="Resigned","Yes","TRUE","No")} -> No
A105: EMP115 | B105: James Gonzalez | C105: IT02 | D105: 43879 | E105: =DATEDIF(D105,TODAY(),"Y")&" Years, "&DATEDIF(D105,TODAY(),"YM")&" Months" -> 6 Years, 4 Months | F105: 53786 | G105: 98 | H105: Active | I105: =VLOOKUP(TRIM(C105),'Lookup Department'!$A$1:$B$7,2,FALSE) -> Information Technology | J105: =IF(G105<=49,"Needs Improvement", IF(G105<=69,"Developing", IF(G105<=84,"Achieving", IF(G105<=94,"Exceeding", "Outstanding")))) -> Outstanding | K105: =IF(J105="Needs Improvement",F105*0, IF(J105="Developing",F105*0.02, IF(J105="Achieving",F105*0.05, IF(J105="Exceeding",F105*0.08, IF(J105="Outstanding",F105*0.12,0))))) -> 6454.32 | L105: {=_xlfn.IFS(Table2[[#This Row],[Employment Status]]="Left","Yes",Table2[[#This Row],[Employment Status]]="Resigned","Yes","TRUE","No")} -> No
A106: EMP092 | B106: Emily Johnson | C106: OPS06 | D106: 42512 | E106: =DATEDIF(D106,TODAY(),"Y")&" Years, "&DATEDIF(D106,TODAY(),"YM")&" Months" -> 10 Years, 1 Months | F106: 81167 | G106: 68 | H106: Active | I106: =VLOOKUP(TRIM(C106),'Lookup Department'!$A$1:$B$7,2,FALSE) -> Operations | J106: =IF(G106<=49,"Needs Improvement", IF(G106<=69,"Developing", IF(G106<=84,"Achieving", IF(G106<=94,"Exceeding", "Outstanding")))) -> Developing | K106: =IF(J106="Needs Improvement",F106*0, IF(J106="Developing",F106*0.02, IF(J106="Achieving",F106*0.05, IF(J106="Exceeding",F106*0.08, IF(J106="Outstanding",F106*0.12,0))))) -> 1623.34 | L106: {=_xlfn.IFS(Table2[[#This Row],[Employment Status]]="Left","Yes",Table2[[#This Row],[Employment Status]]="Resigned","Yes","TRUE","No")} -> No
A107: EMP084 | B107: William Williams | C107: MKT04 | D107: 44349 | E107: =DATEDIF(D107,TODAY(),"Y")&" Years, "&DATEDIF(D107,TODAY(),"YM")&" Months" -> 5 Years, 1 Months | F107: 66688 | G107: 40 | H107: Left | I107: =VLOOKUP(TRIM(C107),'Lookup Department'!$A$1:$B$7,2,FALSE) -> Marketing | J107: =IF(G107<=49,"Needs Improvement", IF(G107<=69,"Developing", IF(G107<=84,"Achieving", IF(G107<=94,"Exceeding", "Outstanding")))) -> Needs Improvement | K107: =IF(J107="Needs Improvement",F107*0, IF(J107="Developing",F107*0.02, IF(J107="Achieving",F107*0.05, IF(J107="Exceeding",F107*0.08, IF(J107="Outstanding",F107*0.12,0))))) -> 0 | L107: {=_xlfn.IFS(Table2[[#This Row],[Employment Status]]="Left","Yes",Table2[[#This Row],[Employment Status]]="Resigned","Yes","TRUE","No")} -> Yes
A108: EMP142 | B108: James Jones | C108: IT02 | D108: 44394 | E108: =DATEDIF(D108,TODAY(),"Y")&" Years, "&DATEDIF(D108,TODAY(),"YM")&" Months" -> 4 Years, 11 Months | F108: 91672 | G108: 88 | H108: Active | I108: =VLOOKUP(TRIM(C108),'Lookup Department'!$A$1:$B$7,2,FALSE) -> Information Technology | J108: =IF(G108<=49,"Needs Improvement", IF(G108<=69,"Developing", IF(G108<=84,"Achieving", IF(G108<=94,"Exceeding", "Outstanding")))) -> Exceeding | K108: =IF(J108="Needs Improvement",F108*0, IF(J108="Developing",F108*0.02, IF(J108="Achieving",F108*0.05, IF(J108="Exceeding",F108*0.08, IF(J108="Outstanding",F108*0.12,0))))) -> 7333.76 | L108: {=_xlfn.IFS(Table2[[#This Row],[Employment Status]]="Left","Yes",Table2[[#This Row],[Employment Status]]="Resigned","Yes","TRUE","No")} -> No
... A151: EMP103 | B151: Amanda Brown | C151: IT02 | D151: 44848 | E151: =DATEDIF(D151,TODAY(),"Y")&" Years, "&DATEDIF(D151,TODAY(),"YM")&" Months" -> 3 Years, 8 Months | F151: 118634 | G151: 91 | H151: Active | I151: =VLOOKUP(TRIM(C151),'Lookup Department'!$A$1:$B$7,2,FALSE) -> Information Technology | J151: =IF(G151<=49,"Needs Improvement", IF(G151<=69,"Developing", IF(G151<=84,"Achieving", IF(G151<=94,"Exceeding", "Outstanding")))) -> Exceeding | K151: =IF(J151="Needs Improvement",F151*0, IF(J151="Developing",F151*0.02, IF(J151="Achieving",F151*0.05, IF(J151="Exceeding",F151*0.08, IF(J151="Outstanding",F151*0.12,0))))) -> 9490.72 | L151: {=_xlfn.IFS(Table2[[#This Row],[Employment Status]]="Left","Yes",Table2[[#This Row],[Employment Status]]="Resigned","Yes","TRUE","No")} -> No
